<?xml version="1.0"?>

<robot xmlns:xacro="http://www.ros.org/wiki/xacro">
  <xacro:macro name="racoonbot" params="prefix">

    <link name="base_footprint"/>

    <joint name="base_joint" type="fixed">
      <parent link="base_footprint"/>
      <child link="base_link" />
      <origin xyz="0 0 0.0625" rpy="0 0 0"/>
    </joint>

    <link name="base_link">
      <visual>
        <geometry>
         <mesh filename="package://racoonbot_pkg/meshes/base_link.dae"/>
        </geometry>
        <origin xyz="0 0 0" rpy="0 0 0"/>
        <material name="white"/>
      </visual>

      <inertial>
        <origin rpy="0 0 0" xyz="0 0 0"/>
        <mass value="0.3"/>
        <inertia ixx="0.3323" ixy="0" ixz="0" iyy="1.0280" iyz="0" izz="1.1346"/>
      </inertial>
    </link>

    <joint name="imu_joint" type="fixed">
      <parent link="base_link"/>
      <child link="imu_link"/>
      <origin xyz="0.0 0 0.005" rpy="0 0 0"/>
    </joint>

    <link name="imu_link"/>

    <joint name="right_motor_link_joint" type="fixed">
      <parent link="base_link"/>
      <child link="right_motor_link" />
      <origin xyz="0.022 -0.040 -0.0125" rpy="0 0 0"/>
    </joint>

    <link name="right_motor_link">
      <visual>
        <geometry>
         <mesh filename="package://racoonbot_pkg/meshes/motor_link.dae"/>
        </geometry>
        <origin xyz="0 0 0" rpy="1.5708 0 0"/>
        <material name="orange"/>
      </visual>

      <inertial>
        <origin rpy="0 0 0" xyz="0 0 0"/>
        <mass value="0.2"/>
        <inertia ixx="0.0015" ixy="0.0" ixz="0.0" iyy="0.0105" iyz="0.0" izz="0.0104"/>
      </inertial>

    </link>

    <joint name="left_motor_link_joint" type="fixed">
      <parent link="base_link"/>
      <child link="left_motor_link" />
      <origin xyz="0.022 0.040 -0.0125" rpy="0 0 0"/>
    </joint>

    <link name="left_motor_link">
      <visual>
        <geometry>
         <mesh filename="package://racoonbot_pkg/meshes/motor_link.dae"/>
        </geometry>
        <origin xyz="0 0 0" rpy="1.5708 0 0"/>
        <material name="orange"/>
      </visual>
      <inertial>
        <origin rpy="0 0 0" xyz="0 0 0"/>
        <mass value="0.2"/>
        <inertia ixx="0.0015" ixy="0" ixz="0" iyy="0.0105" iyz="0" izz="0.0104"/>
      </inertial>

    </link>

    <joint name="right_wheel_joint" type="continuous">
      <parent link="right_motor_link"/>
      <child link="right_wheel_link" />
      <origin xyz="0.021 -0.023 0" rpy="0 0 0"/>
      <axis xyz="0 1 0"/>
    </joint>

    <link name="right_wheel_link">
      <visual>
        <geometry>
         <mesh filename="package://racoonbot_pkg/meshes/wheel_link.dae"/>
        </geometry>
        <origin xyz="0 0 0" rpy="0 0 0"/>
        <material name="black"/>
      </visual>
      <inertial>
        <origin rpy="0 0 0" xyz="0 0 0"/>
        <mass value="0.15"/>
        <inertia ixx="0.0262" ixy="0" ixz="0" iyy="0.0437" iyz="0" izz="0.0262"/>
      </inertial>
    </link>

    <joint name="left_wheel_joint" type="continuous">
      <parent link="left_motor_link"/>
      <child link="left_wheel_link" />
      <origin xyz="0.021 0.023 0" rpy="0 0 0"/>
      <axis xyz="0 1 0"/>
    </joint>

    <link name="left_wheel_link">
      <visual>
        <geometry>
         <mesh filename="package://racoonbot_pkg/meshes/wheel_link.dae"/>
        </geometry>
        <origin xyz="0 0 0" rpy="0 0 0"/>
        <material name="black"/>
      </visual>
      <inertial>
        <origin rpy="0 0 0" xyz="0 0 0"/>
        <mass value="0.15"/>
        <inertia ixx="0.0262" ixy="0" ixz="0" iyy="0.0437" iyz="0" izz="0.0262"/>
      </inertial>
    </link>

    <joint name="caster_link_joint" type="fixed">
      <parent link="base_link"/>
      <child link="caster_link" />
      <origin xyz="-0.080 0 0" rpy="0 0 0"/>
    </joint>

    <link name="caster_link">
      <visual>
        <geometry>
         <mesh filename="package://racoonbot_pkg/meshes/caster_link.dae"/>
        </geometry>
        <origin xyz="0 0 0" rpy="0 0 0"/>
        <material name="black"/>
      </visual>
        <inertial>
        <origin rpy="0 0 0" xyz="0 0 0"/>
        <mass value="0.08"/>
        <inertia ixx="0.0036" ixy="0" ixz="0" iyy="0.0036" iyz="0" izz="0.0015"/>
      </inertial>
    </link>

  </xacro:macro>
</robot>
